2019-04-30,14:05:53.060 :: Failed CarbonLink query 'bib.payments.amazon'
Traceback (most recent call last):
  File "/opt/graphite/webapp/graphite/readers/utils.py", line 110, in merge_with_carbonlink
    cached_datapoints = CarbonLink().query(metric)
  File "/opt/graphite/webapp/graphite/carbonlink.py", line 99, in query
    results = self.send_request(request)
  File "/opt/graphite/webapp/graphite/carbonlink.py", line 132, in send_request
    conn = self.get_connection(host)
  File "/opt/graphite/webapp/graphite/carbonlink.py", line 89, in get_connection
    connection.connect((server, port))
  File "/usr/lib/python2.7/socket.py", line 228, in meth
    return getattr(self._sock,name)(*args)
error: [Errno 111] Connection refused
2019-04-30,14:05:53.083 :: Failed CarbonLink query 'bib.payments.walmart'
Traceback (most recent call last):
  File "/opt/graphite/webapp/graphite/readers/utils.py", line 110, in merge_with_carbonlink
    cached_datapoints = CarbonLink().query(metric)
  File "/opt/graphite/webapp/graphite/carbonlink.py", line 99, in query
    results = self.send_request(request)
  File "/opt/graphite/webapp/graphite/carbonlink.py", line 132, in send_request
    conn = self.get_connection(host)
  File "/opt/graphite/webapp/graphite/carbonlink.py", line 89, in get_connection
    connection.connect((server, port))
  File "/usr/lib/python2.7/socket.py", line 228, in meth
    return getattr(self._sock,name)(*args)
error: [Errno 111] Connection refused
