[2019-04-25 19:10:38 +0000] [11] [INFO] Starting gunicorn 19.9.0
[2019-04-25 19:10:38 +0000] [11] [INFO] Listening at: http://127.0.0.1:8000 (11)
[2019-04-25 19:10:38 +0000] [11] [INFO] Using worker: sync
[2019-04-25 19:10:38 +0000] [32] [INFO] Booting worker with pid: 32
[2019-04-25 19:10:38 +0000] [33] [INFO] Booting worker with pid: 33
[2019-04-25 19:10:38 +0000] [41] [INFO] Booting worker with pid: 41
[2019-04-25 19:10:38 +0000] [43] [INFO] Booting worker with pid: 43
/opt/graphite/webapp/graphite/local_settings.py:334: UserWarning: SECRET_KEY is set to an unsafe default. This should be set in local_settings.py for better security
/opt/graphite/webapp/graphite/local_settings.py:334: UserWarning: SECRET_KEY is set to an unsafe default. This should be set in local_settings.py for better security
/opt/graphite/webapp/graphite/local_settings.py:334: UserWarning: SECRET_KEY is set to an unsafe default. This should be set in local_settings.py for better security
/opt/graphite/webapp/graphite/local_settings.py:334: UserWarning: SECRET_KEY is set to an unsafe default. This should be set in local_settings.py for better security
/usr/lib/python2.7/site-packages/whitenoise/base.py:104: UserWarning: No directory at: /opt/graphite/static/
  warnings.warn(u'No directory at: {}'.format(root))
/usr/lib/python2.7/site-packages/whitenoise/base.py:104: UserWarning: No directory at: /opt/graphite/static/
  warnings.warn(u'No directory at: {}'.format(root))
/usr/lib/python2.7/site-packages/whitenoise/base.py:104: UserWarning: No directory at: /opt/graphite/static/
  warnings.warn(u'No directory at: {}'.format(root))
/usr/lib/python2.7/site-packages/whitenoise/base.py:104: UserWarning: No directory at: /opt/graphite/static/
  warnings.warn(u'No directory at: {}'.format(root))
Traceback (most recent call last):
  File "/usr/lib/python2.7/logging/handlers.py", line 77, in emit
    self.doRollover()
  File "/usr/lib/python2.7/logging/handlers.py", line 350, in doRollover
    os.rename(self.baseFilename, dfn)
OSError: [Errno 2] No such file or directory
Logged from file logger.py, line 97
Traceback (most recent call last):
  File "/usr/lib/python2.7/logging/handlers.py", line 77, in emit
    self.doRollover()
  File "/usr/lib/python2.7/logging/handlers.py", line 350, in doRollover
    os.rename(self.baseFilename, dfn)
OSError: [Errno 2] No such file or directory
Logged from file logger.py, line 97
